Workbook

Sheet README
A1: E4L Leads — daily batch
A2: Eat 4 Life Marketing · AI Marketing Made Easy · built by Claude, reviewed by humans
A4: What this is
A5: The review sheet for E4L's daily lead machine. Claude finds, qualifies, and researches 25 small-business leads per weekday and writes them here. Sam works the Sam Call Sheet tab (calls + follow-ups); Chosen reviews the Leads tab, approves, and loads approved rows into GoHighLevel (E4L Services sub-account). Nothing is emailed or called from this sheet itself.
A6: Daily batches arrive as dated sheets in the same Drive folder ('E4L Leads — YYYY-MM-DD'). This master file holds the playbook tabs, the suppression list, and the run log so the whole system is readable in one place.
A8: Sam: working the Call Sheet
A9: Open the Sam Call Sheet tab. Rows are sorted by Lead Score; every row has the best number, the owner's name and title, the timezone and best time to call, who answers the phone, a 20-second opener written for that business, the call angle, and the objection to expect.
A10: Cadence: Call 1 on the day the batch lands (use Best Time to Call). Call 2 two days later, leave a voicemail. Call 3 three days after that. Then the email bridge. 'Next Call Due' computes itself from what you log.
A11: Log every call the same day with the outcome dropdowns. Every call ends with ask #1 (Game Plan Call → log 'Game Plan Call booked' and the date) or ask #2 (email for the free GEO audit → log 'Email captured' and paste the address). 'Do not call' is permanent — those companies go on the Suppression tab.
A13: Chosen / Rozel: daily review in 5 steps (≈30 minutes for 25 rows)
A14: 1. Open the Leads tab (full research). Rows are sorted by Lead Score. Read Why Now, Attitude Type, Pain Signals, and the Personalized First Line.
A15: 2. Set Review Decision: Approve (load into GHL), Hold (good but not now), Reject (wrong fit — tell us why in Reviewer Notes so the rubric learns).
... A35: Green / amber / red score — Score band: 80–100 send today · 60–79 worth a touch · below 60 hold or reject.

Sheet Sam Call Sheet
A1: Lead ID | B1: Company | C1: Owner | D1: Title | E1: Best Number to Call | F1: Company Phone | G1: City | H1: ST | I1: TZ | J1: Best Time to Call | K1: Business Hours | L1: Gatekeeper Notes | M1: Score | N1: Attitude | O1: Entry Offer | P1: Call Opener (20 sec) | Q1: Call Angle | R1: Likely Objection | S1: Best Opening Moment | T1: After-Hours Handling | U1: Call 1 Date | V1: Call 1 Outcome | W1: Call 2 Date | X1: Call 2 Outcome | Y1: Call 3 Date | Z1: Call 3 Outcome | AA1: Next Call Due | AB1: Email Captured | AC1: Game Plan Call Date | AD1: Sam Notes | AE1: Website | AF1: Owner Email
A2: 20261012-01 | B2: Howard Injury Law | C2: Glen Howard | D2: Attorney | E2: Not found (a client review says Glen shared his personal cell, but no direct line is published; main line +1 702-331-5722, fax +1 702-629-7161 per site and NV Bar) | F2: +1 702-331-5722 | G2: Las Vegas | H2: NV | I2: America/Los_Angeles - Pacific Time (PDT, UTC-7 in October); Las Vegas, NV | J2: Tue-Thu 9:00-10:30 AM PT, right after the office opens at 9 and before Glen is on adjuster calls/court (he negotiates every bodily-injury case personally per the site FAQ schema); fallback Tue-Thu 4:00-4:45 PM PT before the 5 PM close. Avoid Mondays (post-weekend intake pile-up for a 3-person case team). The main line is CallRail-tracked and staffed by the case team during 9-5; ask for Glen by first name. | K2: Office: 'Monday to Friday, 9AM to 5PM PST' (site contact block, https://www.howardinjurylaw.com/contact-us/ and footer). Same page/header also says 'Free Consultation · Available 24/7' and JSON-LD Attorney schema claims openingHours 'Mo,Tu,We,Th,Fr,Sa,Su 24/7' (00:00-23:59). Spanish page: 'De lunes a viernes, de 9:00 a 17:00 (hora del Pacifico)' vs 'Consulta gratuita las 24 horas, los 7 dias de la semana'. GBP hours not opened directly. | L2: Main line +1 702-331-5722 is the office line (CallRail dynamic-swap tracked); no receptionist is named anywhere. Case team per About page (https://www.howardinjurylaw.com/about-us/): James Martin (15+ yrs legal field, role not stated; several Google reviews on the site name James, one calls him the case manager), Vanessa Kitchen (20+ yrs medical field, 10+ yrs practice administrator and marketing - most likely the office/ops lead and the best internal champion), Nathalie Sanabria (case manager). No answering service, call center or AI receptionist is credited; after hours the only named channel is the Intaker chat/text widget ('our 24/7 chat below'; YouTube bio '24/7 Help: intaker.com/howardinjurylaw/pi'). A Google review on the site says 'I had the lawyers personal cell number' - the cell is NOT published; do not ask for it. If the team answers: 'Hi, is Glen in? It's Sam - it's about the 24/7 line on the website.' If Vanessa answers, pitch her as champion (she ran a medical-practice front desk) and ask for 15 minutes with Glen. Careers page is 404; no job posts found (Indeed blocked), so no receptionist hire to reference. | M2: 71 | N2: Growth-Minded Operator (secondary: Tech-Forward Early Adopter) - confidence medium | O2: Free GEO audit (Chosen's matrix entry for PI law) paired with a bilingual (English/Spanish) AI voice-receptionist demo line built from howardinjurylaw.com; lead product on the Game Plan Call = AI voice receptionist with empathetic no-advice intake + missed-call text-back / speed-to-lead; GEO as the add-on. No prices in any asset. | P2: "Hi Glen, this is Sam with Eat 4 Life Marketing - this is a cold call, so feel free to hang up on me. I was on howardinjurylaw.com last night: the header says 'Free Case Review, 24/7, Talk with Glen,' and your contact page says Monday to Friday, 9 to 5. When a crash victim calls at 9pm, or calls in Spanish, who picks up right now - you, voicemail, or nobody? We build an AI receptionist trained on your own site that answers those calls, does a no-advice intake in English or Spanish, and books the consult - and we put a demo line on the phone you can call before you pay a dollar. Can I take 20 seconds to tell you how it works, or should I just send the demo number to ghoward@?" | Q2: Missed-call / after-hours bilingual intake is the wedge; the free GEO audit is the door-opener. Acknowledge he already pays for calls (CallRail tracking, Meta pixel, an ads agency) and that the site promises 24/7 in four languages with one attorney and three staff on a 9-to-5 office line. E4L's receptionist, trained on his own site, answers every missed or after-hours call, runs an empathetic intake (date of injury, treatment, insurer, no legal advice) in English or Spanish, books the consult, and texts back every missed call in under a minute - the caller never reaches the next firm on Google. Proof lever: a demo line built from howardinjurylaw.com he can call before paying anything. Respect his Intaker chat: it handles web chat/text, not the ringing phone. Never promise case volume or outcomes. | R2: 'We're already covered 24/7 - we have Intaker chat and texting, and clients can reach me on my cell.' Answer: chat and text catch the people who type; the voice agent catches the ones who dial at 9pm and get voicemail, and it drops them into the same intake - go-live is one conditional call-forwarding rule on missed/busy calls. Second objection: 'We already have an agency (Storm Media) doing SEO and GEO' - the audit is free, show the screenshots, do not bash the agency; pivot to the phone. Third (PI-specific): 'I get pitched by marketing guys every day' - lead with the demo number and one verifiable observation, not a pitch. | S2: The 24/7 promise on a one-attorney firm: homepage 'Free Case Review - 24/7 Talk with Glen!' and 'we're available 24/7 at (702) 331-5722' vs the contact block 'Monday to Friday, 9AM to 5PM PST' (https://www.howardinjurylaw.com/ and /contact-us/). Neutral, verifiable in 10 seconds, ties straight to the after-hours/bilingual intake gap. Secondary: his own 'we trained there' insurance-defense angle - he sells on knowing the other side's playbook, so frame E4L as showing him the caller's side of the phone. | T2: Site claims 'Available 24/7', 'Free Case Review - 24/7 Talk with Glen!' and 'Give us a call, we're available 24/7 at (702) 331-5722' while the contact block lists office hours 'Monday to Friday, 9AM to 5PM PST'. No answering service, call center or AI receptionist is named on the site, in page source, on BBB or on YouTube. The only named 24/7 channel is the Intaker chat/text widget ('fill out our simple form or our 24/7 chat below'; YouTube bio '24/7 Help: https://www.intaker.com/howardinjurylaw/pi') - chat/SMS, not phone. A client review on the site says 'I had the lawyers personal cell number', suggesting after-hours calls fall to Glen's own cell. GBP hours not opened directly. | AA2: =IF(A2="","",IF(OR(V2="Game Plan Call booked",V2="Do not call",V2="Not interested",V2="Email captured (GEO audit)",X2="Game Plan Call booked",X2="Do not call",X2="Not interested",X2="Email captured (GEO audit)",Y2<>""),"Done",IF(W2<>"",W2+3,IF(U2<>"",U2+2,"Call today")))) | AE2: https://www.howardinjurylaw.com | AF2: ghoward@howardinjurylaw.com
A3: 20261012-02 | B3: Viking Heating & Air Conditioning | C3: Nicole Bridge | D3: Owner / Member | E3: +1 480-689-5167 | F3: +1 480-689-5167 | G3: Chandler | H3: AZ | I3: AZ (Arizona, MST year-round, no DST; same clock as Los Angeles until Nov 1, 2026, then one hour ahead of LA) | J3: Tue-Thu 7:30-8:30 AM AZ (same as LA time until Nov 1): a one-office shop builds the day's dispatch board then, and with the dispatcher seat open the person on the main line is most likely Nikki (Member/Owner, registered agent, office side) rather than a hired gatekeeper. Second window Tue-Thu 4:00-5:30 PM AZ when Kelly (HVAC Tech/Owner) is back from the field. Avoid 9 AM-3 PM, when the line is fielding same-day no-cool calls during fall tune-up season, and avoid Mondays (weekend backlog) and Friday afternoons. | K3: No office hours published on viking-hvac.com, the careers page or BBB. Homepage and blog JSON-LD say open 00:00-23:59 Mon-Sun, and the Google Business Profile mirror (serviceagent.ai) shows 'Open 24 hours' every day with a 'Direct line - speak to a representative'; the site markets '24/7 emergency service' with 'emergency technicians always on call'. In practice it is a one-office shop whose dispatcher role is 'full-time, in-person' running a daily board, so treat the office as weekday daytime (roughly 7 AM-5 PM AZ) with the 24/7 line layered on top. | L3: Main line 480-689-5167 is the only number anywhere (site header, contact page, careers page, BBB, BuildZoom); CallRail is in the site code but the number matches every third-party record, so it is the real line, not a swapped tracking number. No office manager, receptionist, dispatcher or answering-service name is public, and the HVAC Dispatcher seat is currently open (full-time, in-person), so expect Nikki/Nicole Bridge or whoever is covering the board to pick up; no third-party answering service is mentioned anywhere. Kelly Bridge is 'HVAC Tech./Owner' and in the field - do not expect him midday. Ask for 'Nikki' (their own careers page uses that name; BBB has 'Nicole E. Bridge'). If a tech or fill-in answers: 'Is Nikki in the office this morning? It's about the dispatcher opening on your careers page' - true and specific. Their careers page brags 'Decisions made by people you actually know - Nikki and Kelly - not a call center in another state', so position the demo as backup for after hours and busy lines, never as replacing the dispatcher. No owner cell published; no 'no solicitation' notice seen. Second touch only: info@viking-hvac.com (generic, from their JSON-LD) addressed to Nikki or Kelly. Do not cite the Oct 2025 commercial-expansion press release (now 404); a tech named Logan Bridge appears in a recent review - do not assume a family relation. | M3: 69 | N3: Growth-Minded Operator | O3: Voice AI live demo built from viking-hvac.com (DEMO PATH, call-first to Sam with the demo number; email to info@ only as a gatekeeper-friendly second touch), framed on heating-season tune-up volume and the open dispatcher seat; add missed-call text-back. Do not lead with GEO - FAQ schema and an active blog already exist. | P3: Nikki? Sam with Eat 4 Life Marketing out of LA - and this is a cold call, so feel free to hang up on me. I was on Viking's careers page: you're hiring a dispatcher to run the daily board while the site promises 24/7 emergency service across 36 cities. We built a receptionist demo trained on viking-hvac.com that picks up the no-cool calls that ring while your dispatcher is on another line or after the office clears out, and books them. Can I take twenty seconds to tell you how it works, and you decide if it's worth a longer look? | Q3: Nikki, you're hiring a dispatcher at $21-25 an hour and telling 36 cities you're there 24/7. We built a receptionist demo from viking-hvac.com you can call right now: it picks up the calls that ring while your dispatcher is on another line or after hours, qualifies the no-cool emergency, and books it so nothing waits for the morning. Go-live is one call-forwarding rule for missed and busy calls, rollback is one dial code, and it can hand bookings to your existing Service Fusion setup. | R3: 'We run Service Fusion and we're hiring a dispatcher - we're covered.' Answer: keep both; this only takes the calls that would otherwise hit voicemail (busy, after hours, weekends) and hands the booking back to your dispatcher, so nothing changes for the team during the day - call the demo and judge it yourself before anything is bought. | S3: The live 'HVAC Dispatcher' post ($21-25/hr, 'running the daily dispatch board') paired with the careers line 'Decisions made by people you actually know - Nikki and Kelly - not a call center in another state' (https://blog.viking-hvac.com/careers, seen 2026-10-12): they are hiring for the phone seat and proud that calls stay local, which is exactly the after-hours gap the demo covers without replacing anyone. | T3: Unknown who answers after hours. Site claims: 'available 24/7' (repairs), 'we provide 24/7 emergency HVAC services throughout our entire service area' (FAQ), 'same-day service available for urgent situations'; homepage JSON-LD OpeningHoursSpecification Mon-Sun opens 00:00 closes 23:59; ServiceAgent mirror of GBP: 'Open 24 hours' every day (not verified on Google directly). No visible business hours on the site. No answering service, call center, or AI receptionist mentioned anywhere on site or in page source. Careers: 'not a call center in another state'; the dispatcher role is in-person and 'runs the daily dispatch board' (daytime). Gap = 24/7 promise with no stated after-hours answering mechanism. | AA3: =IF(A3="","",IF(OR(V3="Game Plan Call booked",V3="Do not call",V3="Not interested",V3="Email captured (GEO audit)",X3="Game Plan Call booked",X3="Do not call",X3="Not interested",X3="Email captured (GEO audit)",Y3<>""),"Done",IF(W3<>"",W3+3,IF(U3<>"",U3+2,"Call today")))) | AE3: https://www.viking-hvac.com/ | AF3: info@viking-hvac.com (generic office mailbox; present only in the company's JSON-LD page source on blog.viking-hvac.com and blog.viking-hvac.com/careers, not as visible text; no owner-personal email found on any public page)
A4: 20261012-03 | B4: Bob Heinmiller Air Conditioning, Inc. | C4: Mark Derringer | D4: Owner/President | E4: Not found (no owner cell or direct line on site, BBB, Carrier, or reviews; only the main line, fax, and the alternate 407-422-7657 office number) | F4: +1 407-374-0779 (site header 'Hotline', footer, BBB, DispatchCore). Also published: fax +1 407-422-0790; alternate +1 407-422-7657 (contact-page meta description 'Call Us Today' and Experience.com contact number); Carrier dealer page lists +1 321-319-3980 (different number on Carrier's locator - do not assume it reaches the office) | G4: Orlando | H4: FL | I4: America/New_York (Eastern) | J4: Tue-Thu 8:00-8:30 AM ET (Florida telemarketing floor is 8 AM; call before trucks roll and before the office queue builds - an Aug 11, 2026 public review says a morning caller was told 'she'd have to call me back this afternoon'). Fallback 4:00-5:00 PM ET when installs wrap. Ask for Mark Derringer (Owner/President) by name; if out, ask for Linda Heinmiller (Owner/Corp. Secretary). A 2023 review says the owner did not return four calls, so expect to book a time rather than get him live. | K4: Site publishes NO hours anywhere; only 'Same day and 24/7 emergency service available' and 'You can receive same-day care from a qualified expert 24 hours a day throughout the week' (https://www.bobheinmiller.com/). Google data mirrored by DispatchCore and YellowPages: 'Open 24 hours' Monday-Sunday (listing unclaimed). Sister entity Bob Heinmiller Solar Solutions (1519 W Smith St, same owners) lists Mon-Fri 8:00 AM-5:00 PM, closed Sat-Sun (Birdeye, TrustAnalytica). serviceagent.ai (Google data): 'After-hours and emergency response isn't signaled on the public profile.' | L4: Main line +1 407-374-0779 is answered by office staff, not the owner: Aug 11, 2026 review - 'I call for ac service this morning and the young lady said she'd have to call me back this afternoon' (https://www.solarreviews.com/installers/bob-heinmiller-solar-solutions,-llc.-reviews); a Jan 19, 2023 review on the solar entity names an office staffer 'Ashley' promising a callback 'within the hour' (STALE, role not stated). No office manager or dispatcher named on the site or in reviews; 'Meet Our Staff' lists only Bob Heinmiller (Founder), Linda Heinmiller (Owner/Corp. Secretary), Mark Derringer (Owner/President). Field names in reviews: techs Tyler, Chris; comfort advisor/sales Patrick Liner; installers Michael, Anthony. No answering service, call center, or AI receptionist vendor in page source. No owner cell published. Employment page lists 'Administrative' as an application category (no confirmed opening). Get through by asking for 'Mark Derringer' or 'Linda' by name and offering to book a 20-minute slot rather than pitching the person who answers. | M4: 69 | N4: Family-Legacy Pride Brand (primary); Growth-Minded Operator (secondary). Confidence: high (5+ signals across site, press, BBB, job boards). | O4: Voice AI live demo built from bobheinmiller.com (after-hours and overflow coverage on the hotline, booking into their process), framed as protecting a three-generation name - never as replacing office staff. Secondary ask: the free AI-visibility audit ('named in 0 of 3 so far; full 28-answer run on request'). Route: call-first (Sam) with the demo number; service@ email as backup with gatekeeper-friendly copy. demo_build = yes (D2 >= 9, site scrapable); run_geo_audit = yes (D4 = 6). | P4: "Hi, this is Sam with Eat 4 Life Marketing - this is a cold call, so feel free to hang up on me. I'm trying to reach Mark Derringer. The reason I'm calling: your homepage promises same-day, 24/7 service, but the '24/7 Call Service Support' button actually sends people to a web form, and one of your August reviews describes a morning caller being pushed to an afternoon callback. We build an AI receptionist trained on Bob Heinmiller's own site that picks up every call that rings out after hours or when the office is slammed, qualifies the caller, and books the visit - and you can call a demo line we build from your website before you pay anything. Can I take 20 seconds to tell you how it would work for a three-generation shop like yours, and you tell me if it's worth a longer conversation?" | Q4: Family-legacy protection + after-hours/overflow relief. Reference the 1945 roots and the July 2026 award, then the neutral observation that the homepage promises same-day/24-7 but the '24/7 Call Service Support' button lands on a web form and a recent public review describes a morning call deferred to an afternoon callback (summarize as a pattern; never quote the reviewer). Offer: a demo line trained on Bob Heinmiller's own site that answers what already rings out, qualifies the caller (name, number, address, no-cool vs. maintenance, urgency) and books the visit; go-live is one conditional call-forwarding rule, rollback is one dial code; nothing to pay before they hear it. Close with ask #1 (20-minute Game Plan Call with Sebastian) or ask #2 (an email address for the free AI-search audit - note they are not named for Orlando money questions in the checks run so far while AC's Heating & Air, Belle Air, and Aire Serv are). | R4: 'We already offer 24/7 service and our office handles the phones' / 'We've been here 36 years, referrals are our marketing' (Mark's own words: 'There is no better accolade or recognition than a business referral'). Answer: it only takes the calls that already ring out or get a 'we'll call you back' - referral callers still have to get through; the receptionist is trained on their story so callers still reach 'Bob Heinmiller'; office staff keep every call they answer; conditional forwarding only, no change to the number. Secondary objection: vendor fatigue / 'we have a marketing company' (Orange Rock Media builds the site; E4L is not a web or SEO replacement). | S4: The July 24, 2026 blog post 'Bob Heinmiller Solar Solutions named a 2026 Top Solar Contractor' (https://www.bobheinmiller.com/blog/) - a dated win within 90 days, safe to congratulate, and it pairs with the three-generation story. Then pivot to the neutral phone-process observation (site promises 24/7; the '24/7 Call Service Support' button goes to a web form). | T4: claims_24_7, coverage unverified. Site: 'Same day and 24/7 emergency service available' and '24/7 Call Service Support' (button links to /contact-us/ web form, not a phone line). Google data via unclaimed mirrors: 'Open 24 hours' Mon-Sun. No answering-service, call-center, or AI-receptionist vendor in page source. Sister solar entity lists Mon-Fri 8-5 only. Aug 11, 2026 review shows daytime calls being deferred to callbacks. Sam should record who answers on the first dial. | AA4: =IF(A4="","",IF(OR(V4="Game Plan Call booked",V4="Do not call",V4="Not interested",V4="Email captured (GEO audit)",X4="Game Plan Call booked",X4="Do not call",X4="Not interested",X4="Email captured (GEO audit)",Y4<>""),"Done",IF(W4<>"",W4+3,IF(U4<>"",U4+2,"Call today")))) | AE4: https://www.bobheinmiller.com | AF4: Not found
A5: 20261012-04 | B5: Appalachian Tree Service of Atlanta, Inc. | C5: Ryan Strache | D5: President/Owner | E5: Not found (only the main line +1 404-409-9926 is published on site, BBB and Nextdoor; line type not stated, do not text) | F5: +1 404-409-9926 | G5: Kennesaw | H5: GA | I5: America/New_York (Eastern Time) | J5: Tue–Thu 4:15–5:00 PM ET — the last 45 minutes of his posted Mon–Fri 9–5 window, when a climber-led crew is off the tree and the site says requests are reviewed 'during our stated operating hours'; fallback Mon–Fri 9:00–9:30 AM ET right at opening before the crew rolls. Do not call outside 9–5 ET (closed; voicemail only). | K5: Mon–Fri 9:00 AM–5:00 PM; Sat–Sun Closed for normal operations (contact page, JSON-LD OpeningHoursSpecification, Nextdoor). EXCEPTION on the 48 /storm-damage/{city} pages: 'Weekend calls are accepted for urgent storm inquiries and estimates. No after-hours nighttime dispatch.' Google Business Profile not opened directly. | L5: No office manager, dispatcher or answering service is named anywhere (site, BBB, Nextdoor; no vendor scripts in source). The only mailbox is ryan@, and a Nextdoor reviewer refers to 'Ryan and his staff', so the main line +1 404-409-9926 most likely rings to Ryan or straight to voicemail during a job. Ask for Ryan by first name; if a crew member answers, ask when Ryan reviews estimate requests (site says during 9–5) and call back then. Line type not published — manual dial only, no SMS. If voicemail: leave name, 'built a demo line for Appalachian Tree Service', and let Sebastian's email carry it. | M5: 68 | N5: Growth-Minded Operator (medium confidence: 4 signals across 2 source categories - website + third-party profiles); secondary: Overwhelmed Owner-Operator | O5: Voice AI live demo built from appalachiantreeservice.com (generic home-services template: trade = tree service; scenario = tree down on the house after a storm at 9 PM; the AI qualifies the caller, captures address/damage details and books the first-morning assessment - no nighttime dispatch promised) + missed-call text-back. demo_build = yes (phone-first, D2 = 15, site scrapes cleanly). run_geo_audit = after D4 spot-check. | P5: Hi Ryan, this is Sam with Eat 4 Life Marketing — this is a cold call, so feel free to hang up on me. I was on your site this week: nice October hazard-tree special. I also noticed your storm-damage pages say there's no after-hours nighttime dispatch — which makes sense when you're the one in the tree. We build an AI receptionist trained on your own company that picks up the 9 PM storm call, gets the address and what came down, and books your first morning assessment — and we build the demo line from your website before you pay anything. Can I take 20 seconds to tell you how it works, or is this a bad time? | Q5: Relief + coverage, not growth: he is the climber, the estimator and the inbox, and he is paying to drive calls right now (October 10%-off hazard-tree promo, brand-new site, 48 storm-damage city pages added Sept 1) while evening calls go to voicemail. Pitch the storm-week scenario: an AI receptionist trained on his own site answers the after-hours and overflow calls, qualifies the caller (name, address, what fell, photos via the form link), and books the morning assessment — it never dispatches at night, it just keeps the lead. Proof lever: 'we already built a demo line from your website; call it before you pay a dollar.' Go-live = one conditional call-forwarding rule for missed/busy calls; rollback is one dial code. Ask #1: 20-minute Game Plan Call. Ask #2: the free AI visibility check once D4 runs. Keep it to 3 short lines; do not say he misses calls (reviews praise his response speed) and do NOT say weekends are uncovered (his storm pages accept weekend urgent calls) — say 'after 5 PM' / 'overnight'. | R5: 'I'm a small climber-led crew and I don't do night work — I don't need more calls I can't handle.' Answer: the receptionist does not dispatch anything; it answers, captures the details and books the assessment into the next open morning so you choose the jobs instead of losing them to whoever picked up. Secondary: 'I just rebuilt the site / I handle the phone myself' — it only covers the calls that already go to voicemail, trained on that new site, nothing for you to set up beyond one forwarding rule. Budget sensitivity is likely (solo email, no office staff) — keep pricing for the Game Plan Call. | S5: The live October promotion: 'October Special • Active Oct 1 – Oct 31 — Don't Let Spooky Trees Haunt Your Home — Save 10% This October' on the newly relaunched site (https://www.appalachiantreeservice.com/, seen 2026-10-13). Dated, positive, business-specific and his own words; pairs naturally with 'every call that promo brings in after 5 PM currently waits until morning' (contact page: 'We review requests during our stated operating hours'). | T5: No nighttime coverage claimed. Homepage Service JSON-LD: 'Storm-damage inquiries, assessment and cleanup ... during listed inquiry hours; no nighttime dispatch'. /storm-damage/kennesaw (and 47 sibling city pages, 2026-09-01): 'Storm inquiry hours Monday–Friday: 9:00 AM–5:00 PM for normal operations and dispatch. Saturday–Sunday: Weekend calls accepted for urgent storm inquiries and estimates. There is no after-hours nighttime dispatch.' Contact page: 'We review requests during our stated operating hours.' No 24/7 claim, answering service, AI receptionist or IVR vendor in page source. Gap to pitch = evenings/nights (after 5 PM), NOT weekends. | AA5: =IF(A5="","",IF(OR(V5="Game Plan Call booked",V5="Do not call",V5="Not interested",V5="Email captured (GEO audit)",X5="Game Plan Call booked",X5="Do not call",X5="Not interested",X5="Email captured (GEO audit)",Y5<>""),"Done",IF(W5<>"",W5+3,IF(U5<>"",U5+2,"Call today")))) | AE5: https://www.appalachiantreeservice.com | AF5: ryan@appalachiantreeservice.com
A6: 20261012-05 | B6: Blue Peaks Roofing LLC | C6: Andrew Ubben | D6: Owner | E6: +1 303-808-0687 | F6: +1 303-808-0687 | G6: Littleton | H6: CO | I6: MT | J6: Tue-Thu 8:00-8:45 AM MT, right at office open, before project consultants and crews head out to roofs (hours are 8-5 weekdays and the site funnel is callback-based, so the 303 line is most likely picked up by a live person first thing); fallback Tue-Thu 4:00-4:50 PM MT before the 5 PM close. Avoid Mondays (storm-claim backlog) and anything after 5 PM or weekends, which go to voicemail per the published hours. | K6: Mon-Fri 8:00 AM-5:00 PM, Sat-Sun closed (Parker Chamber member listing 'Mon-Fri - 8am - 5pm'; leadstal GBP mirror shows the same). Site itself lists no hours; it says emergency repairs are handled 'during normal business hours' and 'We call you back to set a time.' | L6: No office manager, dispatcher or receptionist is named anywhere (site, reviews, BBB, chamber, LinkedIn). The only number on the site, BBB, JSON-LD and PRs is (303) 808-0687; no answering service, call tracking or AI receptionist detected, and the site says 'We call you back to set a time,' so expect either whoever is at the desk 8-5 MT or voicemail. Ask for 'Andrew' (Andrew J. Ubben, BBB principal/Owner); if they say the owner is 'Mike' (Mike McCoy, named Owner in 2026 paid press releases), take the hand-off and confirm on the call who owns phones/marketing — do not insist on either name. Public side door: Alyssa McGuinnis, Project Consultant, cell (303) 882-2061 (Parker Chamber rep listing) — sales-side, useful to ask 'who handles the phones and marketing' but not to pitch as owner. Project-side staff named in reviews/LinkedIn (Benny Izquierdo, Grant, John Y., Michael G., Kaleb, Diego Martinez) — if one answers, they are on jobs, keep it to 'who handles after-hours calls and marketing?' and get a callback window. Mirror their line 'the claim stays yours — we never file claims for homeowners'; no claim-handling promises. Do not use (970) 410-3778 or (720) 202-1127 (stale). Do not repeat their unverified Team Dave Logan / Quality Business Awards claims. | M6: 66 | N6: Growth-Minded Operator (secondary: Tech-Forward Early Adopter) — confidence medium | O6: Voice AI live demo line built from bluepeaksroofing.com — after-hours/overflow receptionist that qualifies the caller (address, leak vs. hail, claim status) and books the free inspection — paired with missed-call text-back; Revenue Leak Scorecard as the email CTA (no links until warm-up clears); GEO audit as a later touch once the AI spot-check is run. | P6: Hi, this is Sam with Eat 4 Life Marketing — is this Andrew? Full disclosure, this is a cold call, so you're welcome to hang up on me. I saw Blue Peaks' LinkedIn post this week — a roof replacement shouldn't feel like 'radio silence until a dumpster shows up.' I also noticed your site says emergency repairs are business-hours only, and the Littleton homeowner who calls at 7 PM after a hailstorm is dialing the next roofer on Google. We built a demo receptionist from bluepeaksroofing.com that answers after-hours and overflow calls, asks the leak-or-hail and claim questions your consultants ask, and books the free inspection — you can call it and hear it before anyone talks money. Can I take 20 seconds to tell you how it works, and you tell me if it's worth a longer look? | Q6: Your site says emergency repairs happen during normal business hours and that you call people back to set a time — in hail season that callback window is exactly when a homeowner dials the next roofer who picks up. We built a demo receptionist from bluepeaksroofing.com that answers after hours and overflow calls, asks the leak-or-hail and insurance questions your consultants ask, and books the free inspection; you can call it and hear it before anyone talks money. Go-live is one conditional call-forwarding rule on missed calls and rollback is one dial code, so nothing about how your team works changes. | R6: "We already answer everything — communication is our whole brand, and we have a system (GHL form / marketing vendor)." Answer: keep all of it — this only catches the calls that already ring out after 5pm or while your consultants are on roofs, and books them into whatever you use today; hear the demo first and decide after. | S6: LinkedIn company post ~Oct 10, 2026 (shown as "2d" ago on Oct 12): "A roof replacement shouldn't feel like radio silence until a dumpster shows up." — their own words about communication, 2 days old, safe and positive; URL https://www.linkedin.com/company/blue-peaks-roofing-littleton-co. Backup: July 23, 2026 hail-season inspection expansion release. | T6: Unknown — nothing published. Site home + FAQ: "We make emergency repairs during normal business hours." / FAQ: "Yes. We handle emergency repairs during normal business hours." Contact page: "Emergency repairs are available during business hours." and "We call you back to set a time." No hours listed on the site; no 24/7 claim; no answering service, call center, text-back, or AI receptionist mentioned anywhere in page source. Aggregator-shown GBP hours (unverified): Mon-Fri 8 AM-5 PM, Sat-Sun Closed (https://www.leadstal.com/sb/blue-peaks-roofing). | AA6: =IF(A6="","",IF(OR(V6="Game Plan Call booked",V6="Do not call",V6="Not interested",V6="Email captured (GEO audit)",X6="Game Plan Call booked",X6="Do not call",X6="Not interested",X6="Email captured (GEO audit)",Y6<>""),"Done",IF(W6<>"",W6+3,IF(U6<>"",U6+2,"Call today")))) | AE6: https://bluepeaksroofing.com | AF6: admin@bluepeaksroofing.com
A7: 20261012-06 | B7: Shockley Electric LLC | C7: Christian Shockley | D7: Not found | E7: Not found (only the main line +1 770-630-6858 is published; with a 2-person crew it may be his cell — manual dial only) | F7: +1 770-630-6858 (main line; same number on site tel: links, BBB, Nextdoor, Thumbtack — CONFIRMED. 2-person shop, so this may ring to the owner's cell: manual human dial only, no SMS/AI outbound.) | G7: Marietta | H7: GA | I7: ET | J7: Tue-Thu 8:00-8:50 AM ET, just before the posted 9:00 open and before he is on a ladder; fallback Tue-Thu 4:30-5:30 PM ET as jobs wrap and before the line 'closes' at 5:30. Reason: Thumbtack shows '2 employees' and reviews describe Christian personally doing 4-hour jobs, so mid-day (9:30-4:00) the only published number is in a panel and rings to voicemail. Skip Mondays (solo scheduler's catch-up day) and weekends (Closed). | K7: Mon-Fri 9:00 AM-5:30 PM, Sat-Sun Closed (Nextdoor listing). Thumbtack shows Mon-Fri 9:00 AM-5:00 PM, Sat/Sun Closed. Website lists no hours and no 24/7 claim; Google Business Profile not accessible this session. | L7: No gatekeeper. Two-employee shop (Thumbtack: 'Hired 60 times, 2 employees, 12 years in business'); no office manager, dispatcher, answering service or AI receptionist found on the site, BBB, Nextdoor or Thumbtack, and the single published number 770-630-6858 appears on every page - almost certainly Christian's own cell, so expect him or voicemail. Reviews name only Christian as the person doing the work. A second person replies for the business on Nextdoor (initials 'T. J.', Hiram, GA) - possibly the second employee; if someone else answers, ask for Christian by first name ('Is Christian around? It's Sam'). Ignore the contact-page fax +1 800 889 9898 (placeholder). On voicemail leave a 10-second message naming the demo line, no pitch, and log 'who answered' on first dial. Manual human dial only - no SMS or AI outbound to this number since it may be a personal cell. Tone: terse, anti-upsell ('we do not upsell') - no hype, no 'AI' lead-in, do not quote a Google review count. | M7: 66 | N7: Overwhelmed Owner-Operator (primary, medium confidence); Marketing-Burned Skeptic (secondary) | O7: Voice AI live demo built from shockleyelectric.com (safety-triage branch for sparking/burning-smell calls, panel-upgrade quote capture, books the free estimate) + missed-call text-back. Add the free GEO audit as the second touch once the spot-check is run (no schema on site). | P7: "Christian? Sam with Eat 4 Life Marketing - straight up, this is a cold call, you can hang up on me. Your site says 'call us now to schedule,' and Nextdoor shows the line closing at 5:30 and on weekends. With a two-man crew I'd bet some panel-upgrade calls hit voicemail while you're in a box - and that homeowner just calls the next electrician on Google. We built a demo receptionist from shockleyelectric.com you can call before you pay a dollar - it picks up when you can't, asks if something's sparking, and books the free estimate. Got 20 seconds for me to explain, then you tell me if it's worth a longer look?" | Q7: "Christian, it's Sam with Eat 4 Life Marketing. We built a demo receptionist from shockleyelectric.com you can call right now — it picks up when you're on a ladder or it's after 5:30, asks whether something's sparking or smells hot, and books the free estimate for a panel upgrade. Nothing to buy to hear it; if you don't like it, hang up on it." Qualify: "Who picks up right now when you're mid-job — you, voicemail, or nobody?" | R7: "I answer my own phone — it's just me and one guy, I don't need a receptionist." Answer: "Keep answering. This only catches the calls that already hit voicemail — after 5:30, weekends, when you're in a panel — and books them; go-live is one call-forwarding rule and rollback is one dial code." | S7: The Nextdoor 'Our story' line 'The Electrician Marietta GA Calls First' paired with the posted hours (Mon–Fri 9–5:30, closed weekends) — a neutral, verifiable observation about his phone process that leads straight to the demo (https://nextdoor.com/pages/shockley-electric-marietta-ga/). Backup compliment: Expertise.com 'Best Electricians in Roswell, GA 2026' list updated Oct 8, 2026 (https://www.expertise.com/ga/roswell/electricians); safest brag to mirror: lifetime labor guarantee and 'we do not upsell'. | T7: Unknown / not stated. Hours: Mon–Fri 9:00 AM–5:30 PM, Sat–Sun Closed (Nextdoor; Thumbtack confirms Sun Closed). Site mentions 'emergency repairs' but makes no 24/7 claim, lists no after-hours number, answering service, or AI receptionist, and page source has no answering/AI vendor scripts. With a 2-person crew and phone-only scheduling, after-hours and on-the-job calls most likely reach voicemail (not verified — Sam records 'who answered' on first dial). | AA7: =IF(A7="","",IF(OR(V7="Game Plan Call booked",V7="Do not call",V7="Not interested",V7="Email captured (GEO audit)",X7="Game Plan Call booked",X7="Do not call",X7="Not interested",X7="Email captured (GEO audit)",Y7<>""),"Done",IF(W7<>"",W7+3,IF(U7<>"",U7+2,"Call today")))) | AE7: https://shockleyelectric.com/ | AF7: christian@shockleyelectric.com
A8: 20261012-07 | B8: Light It Up Electric, Inc. | C8: Todd Guernsey | D8: Owner / Texas Master Electrician | E8: Not found (only the main line 469-261-1503 appears on the site, BBB, JSON-LD and the TDLR record) | F8: +1 469-261-1503 (site header/footer tel: link, JSON-LD, BBB, TDLR license record all match) | G8: Frisco | H8: TX | I8: America/Chicago (Central Time) | J8: Tue–Thu 8:05–8:45 AM CT, with 4:00–4:45 PM CT as the fallback. Reason: the site posts 'Reception Hours' starting at 8:00 (contact page/footer) or 9:00 (appointment page), so a staffed office line opens then and crews are least likely to be mid-job early; after 5:00 PM and weekends the line is closed, so never call then. Nothing public says the owner answers the main line, so expect reception and ask for Todd by name. | K8: Mon–Fri 8:00 AM–5:00 PM, Sat–Sun Closed (site footer, FAQ 'We are open Monday through Friday 8:00 am to 5:00 pm', and OpeningHoursSpecification JSON-LD). 'Reception Hours' shown as Mon–Fri 9:00 am–5:00 pm on /schedule-an-appointment but 8:00 am–5:00 pm on /contact — minor conflict. No 24/7 or emergency hours anywhere; live GBP hours not fetched. | L8: The site posts "Reception Hours," so expect a receptionist/office person on 469-261-1503 during 8–5 CT (name not published; BBB lists no customer contact). Natasha Guernsey is named on the company site as the author of every blog post (role not stated) and is the likely office/marketing contact and a possible champion — if she answers, reference the Halloween panel posts. Ask for "Todd Guernsey, the master electrician" by name; no owner cell or direct line is published anywhere public. If routed to email, Info@LightItUpElectric.net is on Google Workspace (good deliverability); LightItUpElect@aol.com is the address the appointment page shows under "Email us." Do not mention family relationships; treat Natasha only as a named company contact. | M8: 66 | N8: Unclear (leans Growth-Minded Operator; Family-Legacy Pride Brand secondary) | O8: Voice AI live demo — an after-hours/overflow receptionist trained on lightitupelectric.net that answers the calls reception misses after 5 PM and on weekends, triages 'sparking/burning smell' urgency, books the estimate, and can mention the Advantage Plan; pair with missed-call text-back and sub-60-second form reply. Ask #2: free AI visibility audit for 'EV charger installer / electrician near Frisco, TX'. | P8: Hi Todd — Sam with Eat 4 Life Marketing. Full disclosure, this is a cold call, so feel free to hang up on me. I was on lightitupelectric.net and the Advantage EV+ plan caught my eye. Here's why I'm calling: your site says "if you need us right now, call us," but reception closes at 5 and all weekend, so a 7 PM panel or EV-charger call hits voicemail and that homeowner calls the next electrician on Google. We built a receptionist trained on your own website that picks those up and books the estimate — you can call it before you pay a dollar. Can I take 20 seconds to explain how it works, and you tell me if it's worth a longer look? | Q8: Coverage gap, not growth: the site tells people "if you need us right now, call us" and promises same-day response, but reception closes at 5 and all weekend, so a warm-outlet, tripped-panel or EV-charger call at 7 PM hits voicemail and that homeowner dials the next electrician — the exact "shop around" problem their own memberships page says they lose to. Proof-first: E4L builds a demo line trained on their own site they can call before paying; go-live is one conditional call-forwarding rule for missed/busy calls, rollback is one dial code, and a human still answers everything they already pick up. Secondary: every after-hours caller the receptionist books is a natural Advantage Plan prospect. | R8: "We're a small family shop and reception already handles the phones — we get back to everyone the same day." Answer: it only touches calls that already go to voicemail (after 5, weekends, line busy); nothing changes about who answers during the day; hear the demo first, no commitment. Expect pragmatic skepticism of marketing vendors (niche read: allergic to hype, will try to break the demo) — lead with the demo number, not features, and never say "AI" first. | S8: The Advantage EV+ membership plan plus the twice-weekly Halloween-themed blog run (Oct 6 'No Tricks — Just a Safer Home', Oct 8 'Frankenstein Says: Check the Panel!'), both dated within the last 7 days on https://www.lightitupelectric.net/blog and /memberships — recent, specific, positive, and about their business. Fallback: 'Voted Best Electrician in Frisco' banner (undated) and 26 years family-owned. | T8: hours_only. Site/JSON-LD: Mon–Fri 08:00–17:00, 'Saturday to Sunday : Closed'; no 24/7, emergency-line, answering-service, call-center or AI-receptionist text anywhere in the fetched source of /, /contact, /schedule-an-appointment, /faqs, /memberships. Yet the site promises 'Same-Day Response' (memberships page), 'Will Get Back To You The Same Day' (home), 'If you need us right now call us at 469-261-1503' (form confirmation), and the FAQ tells warm-outlet callers to 'call us immediately'. After 5 PM and all weekend the only path is voicemail or a form answered 'as soon as possible'. | AA8: =IF(A8="","",IF(OR(V8="Game Plan Call booked",V8="Do not call",V8="Not interested",V8="Email captured (GEO audit)",X8="Game Plan Call booked",X8="Do not call",X8="Not interested",X8="Email captured (GEO audit)",Y8<>""),"Done",IF(W8<>"",W8+3,IF(U8<>"",U8+2,"Call today")))) | AE8: https://www.lightitupelectric.net | AF8: Info@LightItUpElectric.net
A9: 20261012-08 | B9: By The Book Plumbing LLC | C9: James Smith | D9: Owner / Co-founder | E9: Not found (only the main line 281-907-2092 is published; the TSBPE RMP record lists no phone) | F9: +1 281-907-2092 | G9: Spring | H9: TX | I9: CT | J9: Tue-Thu 7:30-8:00 AM CT, before his first job (listed hours start at 8 AM), with a backup window 4:00-5:00 PM CT right after listed hours end. Reason: no office staff, dispatcher or answering service appears in any public source; reviews show James schedules and does the work himself ('James offered the first available appointment'; review replies signed '-James'), so midday he is under a water heater and the published line likely rings to him. Avoid Monday mornings (weekend backlog) and Friday after 2 PM. | K9: Mon-Fri 8:00 AM-4:00 PM; Sat-Sun Closed (Google Business Profile mirror via LeadsTal and the Nextdoor business page agree). The site's Spring TX page claims 'round-the-clock' emergency response and Yelp reportedly lists 'open 24 hours', but (281) 907-2092 is the only published line and no after-hours coverage is named. | L9: No gatekeeper found. No office manager, dispatcher, receptionist or answering service is named on the site, Nextdoor, Trustindex (727 reviews), the GBP mirror, conroedirect or the 2018 Voyage Houston interview; the TSBPE record lists no phone. The only published number, (281) 907-2092, appears to ring to James himself (he schedules jobs personally per reviews and signs replies '-James'), and it may be his cell, so human dial only, no SMS or AI voice to that line. Dana Smith is named co-founder on the homepage (the 2018 interview mentions his wife without a role); if she answers, ask for James by name and say it is about the Saturday and after-4 PM calls. If voicemail: leave a 10-second message naming the demo line, then email james@bythebookplumbing.com (printed in the site footer). Neighbors call him 'old school' and code-driven, so do not open with 'AI'; stress it is trained on his site and answers as By The Book. | M9: 65 | N9: Overwhelmed Owner-Operator (medium confidence; secondary Family-Legacy Pride cues) | O9: Voice AI live demo built from bythebookplumbing.com with the emergency/after-hours angle, paired with missed-call text-back (door-opener = demo number; D2 = 15 and the site is scrapable, but throttle the scraper - the site WAF began returning 403 after roughly 15 rapid fetches). Run the GEO audit before send since D4 is unchecked. | P9: James? Sam with Eat 4 Life Marketing. This is a cold call, so I'll be quick. Your Google listing closes at four and shows weekends off, but your Spring page promises round-the-clock emergency service, so I'm guessing a Saturday water-heater leak hits voicemail while you're under a tank, and that homeowner calls the next name on Google. We build a receptionist trained on your own site that answers as By The Book, books the job, and texts back every missed call in under a minute. You can call it and hear it before you pay a dollar. Can I take twenty seconds to tell you how the demo line works, and if it's not for you, I'll let you go? | Q9: James, your Google listing says you offer emergency plumbing, but hours stop at 4 and weekends show closed, so a Saturday-night water-heater leak in Spring probably lands in voicemail and that homeowner calls the next plumber on Google. We built a receptionist from your own website that picks up those calls, gets the name, address and what's leaking, books it or texts them back in under a minute, and you can hear it answer as By The Book before you pay anything. Going live is one call-forwarding rule for missed calls, and one dial code turns it off. | R9: "It's just me, I'm already booked a week out, and I don't want a robot talking to my customers." Answer: it only takes the calls you already can't (missed, after 4pm, weekends), introduces itself as By The Book's assistant, captures the water-heater and tankless jobs you want and politely refers the rest, so the schedule fills with the right work instead of callers going to the next plumber; hear it on the demo line first, nothing to buy until you have. | S9: 671 Google reviews at 5.0 that name James personally (Trustindex) set against the GBP listing that says "Yes, we offer emergency plumbing services" while hours read Mon-Fri 8 AM-4 PM, Sat/Sun Closed (LeadsTal GBP mirror) - a neutral, verifiable observation about who picks up the phone. Backup: Nextdoor neighbors calling him "old school" and "a hidden gem". | T9: Unknown / no coverage stated. GBP mirror (LeadsTal) and the Nextdoor business page both list Mon-Fri 8 AM-4 PM, Sat/Sun Closed. The site's Spring TX landing page (https://bythebookplumbing.com/spring-texas/) DOES claim 'Plumbing problems don't adhere to regular business hours, and neither do we… providing round-the-clock services when you need them' (home/about/contact pages make no 24/7 claim). No answering service, office line, dispatcher or after-hours number is published anywhere. Yelp reportedly lists 'open 24 hours' (page could not be opened). Who picks up after 4 PM or on weekends is not stated. | AA9: =IF(A9="","",IF(OR(V9="Game Plan Call booked",V9="Do not call",V9="Not interested",V9="Email captured (GEO audit)",X9="Game Plan Call booked",X9="Do not call",X9="Not interested",X9="Email captured (GEO audit)",Y9<>""),"Done",IF(W9<>"",W9+3,IF(U9<>"",U9+2,"Call today")))) | AE9: https://bythebookplumbing.com/ | AF9: james@bythebookplumbing.com
A10: 20261012-09 | B10: ScissorTail Roofing & Construction | C10: Matt Morgan | D10: Owner | E10: +1 405-452-0591 — LIKELY, not confirmed as owner-direct: listed as "Contact phone" under "Contact name Matt Morgan" in the May 5, 2025 GetFeatured press placement media-contact block; scout noted an older directory shows it as the Norman office line; not labeled cell/direct anywhere. Manual human dial only; line type unknown. | F10: +1 405-928-8089 (site header/footer tel link, Contact page, BBB — CONFIRMED main line) | G10: Norman | H10: OK | I10: America/Chicago — Central Time (CDT in October, UTC-5) | J10: Tue–Thu 8:00–8:45 AM CT, right at office open before account managers and production staff head to job sites (office line staffed from 8:00 per site hours; trades window per playbook); fallback Tue–Thu 4:30–5:45 PM CT before the 6:00 PM close when field staff are back. Avoid Mondays (storm-week callback backlog) and anything outside 8–6 (site says after-hours is emergencies only). | K10: Mon–Fri 8:00 AM–6:00 PM; Saturday and Sunday "By Appointment"; "24/7 Emergency Services Available" / "around the clock for emergencies" (site homepage, Contact page, JSON-LD openingHoursSpecification Mon–Fri 08:00–18:00). Google Business Profile hours not readable this run. | L10: Who answers the main line (405) 928-8089 is not published — no office manager/dispatcher named on site, BBB, or reviews (reviews not readable). Published contact is Matt Seaton, Director of Operations (matt.seaton@scissortailroofing.com; "regularly find him in the field talking with our customers"). Account-management team that likely fields inbound: Lance Uhles (Director), Nich Lanier and Mitchell Smith (Account Managers). The estimate widget says messages go to "his personal phone" — unnamed. Two Matts: ask for "Matt Seaton" first (he is the published contact and runs operations/efficiency programs — natural champion), then "Matt Morgan, the owner". Second line (405) 452-0591 is tied to Matt Morgan as media contact in the May 2025 press release — try it only as a manual dial if the main line stalls. No answering service or IVR detected. | M10: 65 | N10: Growth-Minded Operator (secondary: Tech-Forward Early Adopter) — medium confidence | O10: Voice AI live demo line built from scissortailroofing.com — positioned as after-hours/overflow coverage behind their own "Responses within 2 hrs" promise: answers the 24/7 emergency line when the personal phone is on a roof, qualifies storm/leak urgency, captures address + insurance status, books the free estimate; pair with missed-call text-back on the SMS-consented estimate form. GEO audit only as a secondary touch (site already schema-ready). demo_build = yes (D2 = 15, site scrapable, 38 clean pages). | P10: "Hi, this is Sam with Eat 4 Life Marketing — this is a cold call, so feel free to hang up on me. I was on scissortailroofing.com and saw you promise 24/7 emergency service across Central Oklahoma while the office runs eight to six, and estimate requests go straight to somebody's personal phone. We built a demo receptionist for ScissorTail from your own site — it only picks up the calls that ring out after six or during a hail week, qualifies the caller, and books the free estimate. Can I take twenty seconds to tell you how it works, and you tell me whether it's worth hearing?" | Q10: Missed-call / after-hours voice demo. Matt Morgan spent 15 years in software management and the company already runs a GEO-ready site, so skip "AI education" and GEO; lead with proof: a demo receptionist already built from their own site that only takes the calls that ring out after 6pm, on weekends ("By Appointment"), and during hail-week surges across 9 cities — then books the free estimate and texts the caller back. Frame it as protecting the "Responses within 2 hrs" promise and the Google Guaranteed leads they are already paying for, not replacing Matt Seaton's team. Secondary champion: Matt Seaton (Director of Operations, "operation and efficiency programs") — the demo is something he can forward to the three owners. | R10: "It goes straight to my personal phone and we respond within two hours — we don't miss calls." Response: agree, and point out the demo only picks up when that phone can't (on a roof, after 6, Sunday storm night); offer to let them call the demo line and hear it; go-live is one conditional call-forward rule on missed/busy calls, rollback is one dial code. Second objection: "we already have a new website / we're Google Guaranteed" — reply that this is about the calls those investments generate, not more marketing. | S10: Matt Morgan serving as Board President of the Oklahoma Roofing Contractors Association (site About; undated) — safe, professional compliment. Operational hook: the site promises "24/7 Emergency Services Available" / "Responses within 2 hrs" while hours are Mon–Fri 8–6 and estimate texts go "straight to my personal phone" (homepage). Secondary: new website built ~May 2026 (robots.txt "Generated: May 2026", Astro v6.2.1, © 2026). | T10: claims_24_7 with hours_only staffing — Site: "24/7 Emergency Services Available" (homepage badge), FAQ: "Yes, we provide 24/7 emergency roofing services for storm damage and urgent repairs across Central Oklahoma", Norman page: "Emergency response available 24/7"; Contact page: "We are available Monday through Friday from 8a to 6p, by appointment outside those hours, and around the clock for emergencies"; hours block "Mon–Fri 8:00 AM - 6:00 PM · Sat By Appointment · Sun By Appointment"; header promise "Responses within 2 hrs". Estimate widget: "Replies on his personal phone — This text goes straight to my personal phone." No answering service, IVR, call center, or AI receptionist mentioned anywhere on site or in page source. Who actually answers after 6pm: Not found. | AA10: =IF(A10="","",IF(OR(V10="Game Plan Call booked",V10="Do not call",V10="Not interested",V10="Email captured (GEO audit)",X10="Game Plan Call booked",X10="Do not call",X10="Not interested",X10="Email captured (GEO audit)",Y10<>""),"Done",IF(W10<>"",W10+3,IF(U10<>"",U10+2,"Call today")))) | AE10: https://www.scissortailroofing.com | AF10: Not found for the owner. Only published address: matt.seaton@scissortailroofing.com — belongs to Matt Seaton, Director of Operations (NOT an owner); shown on homepage ("Call us at 405-928-8089 or email matt.seaton@scissortailroofing.com to describe your project") and About page; MX present (smtp.google.com)
